Workbook

Sheet Table Form
A1: Sector | B1: Year | C1: Month | D1: Cereals and products | E1: Meat and fish | F1: Egg | G1: Milk and products | H1: Oils and fats | I1: Fruits | J1: Vegetables | K1: Pulses and products | L1: Sugar and Confectionery | M1: Spices | N1: Non-alcoholic beverages | O1: Prepared meals, snacks, sweets etc. | P1: Food and beverages | Q1: Clothing | R1: Footwear | S1: Clothing and footwear | T1: Housing | U1: Fuel and light | V1: Household goods and services | W1: Health | X1: Personal care and effects | Y1: Transport and communication | Z1: Recreation and amusement | AA1: Education | AB1: Pan, tobacco and intoxicants | AC1: Miscellaneous | AD1: General index
A2: Rural | B2: 2013 | C2: January | D2: 107.5 | E2: 106.3 | F2: 108.1 | G2: 104.9 | H2: 106.1 | I2: 103.9 | J2: 101.9 | K2: 106.1 | L2: 106.8 | M2: 103.1 | N2: 104.8 | O2: 106.7 | P2: 105.5 | Q2: 106.5 | R2: 105.8 | S2: 106.4 | T2: 139.2561 | U2: 105.5 | V2: 104.8 | W2: 104 | X2: 104.7 | Y2: 103.3 | Z2: 103.4 | AA2: 103.8 | AB2: 105.1 | AC2: 104 | AD2: 105.1
A3: Urban | B3: 2013 | C3: January | D3: 110.5 | E3: 109.1 | F3: 113 | G3: 103.6 | H3: 103.4 | I3: 102.3 | J3: 102.9 | K3: 105.8 | L3: 105.1 | M3: 101.8 | N3: 105.1 | O3: 107.9 | P3: 105.9 | Q3: 105.9 | R3: 105 | S3: 105.8 | T3: 139.2561 | U3: 105.4 | V3: 104.8 | W3: 104.1 | X3: 104.3 | Y3: 103.2 | Z3: 102.9 | AA3: 103.5 | AB3: 105.2 | AC3: 103.7 | AD3: 104
A4: Rural+Urban | B4: 2013 | C4: January | D4: 108.4 | E4: 107.3 | F4: 110 | G4: 104.4 | H4: 105.1 | I4: 103.2 | J4: 102.2 | K4: 106 | L4: 106.2 | M4: 102.7 | N4: 104.9 | O4: 107.3 | P4: 105.6 | Q4: 106.3 | R4: 105.5 | S4: 106.2 | T4: 139.2561 | U4: 105.5 | V4: 104.8 | W4: 104 | X4: 104.5 | Y4: 103.2 | Z4: 103.1 | AA4: 103.6 | AB4: 105.1 | AC4: 103.9 | AD4: 104.6
A5: Rural | B5: 2013 | C5: February | D5: 109.2 | E5: 108.7 | F5: 110.2 | G5: 105.4 | H5: 106.7 | I5: 104 | J5: 102.4 | K5: 105.9 | L5: 105.7 | M5: 103.1 | N5: 105.1 | O5: 107.7 | P5: 106.3 | Q5: 107.1 | R5: 106.3 | S5: 107 | T5: 139.2561 | U5: 106.2 | V5: 105.2 | W5: 104.4 | X5: 104.6 | Y5: 103.9 | Z5: 104 | AA5: 104.1 | AB5: 105.6 | AC5: 104.4 | AD5: 105.8
A6: Urban | B6: 2013 | C6: February | D6: 112.9 | E6: 112.9 | F6: 116.9 | G6: 104 | H6: 103.5 | I6: 103.1 | J6: 104.9 | K6: 104.1 | L6: 103.8 | M6: 102.3 | N6: 106 | O6: 109 | P6: 107.2 | Q6: 106.6 | R6: 105.5 | S6: 106.4 | T6: 139.2561 | U6: 105.7 | V6: 105.2 | W6: 104.7 | X6: 104.3 | Y6: 104.4 | Z6: 103.3 | AA6: 103.7 | AB6: 106 | AC6: 104.3 | AD6: 104.7
A7: Rural+Urban | B7: 2013 | C7: February | D7: 110.4 | E7: 110.2 | F7: 112.8 | G7: 104.9 | H7: 105.5 | I7: 103.6 | J7: 103.2 | K7: 105.3 | L7: 105.1 | M7: 102.8 | N7: 105.5 | O7: 108.3 | P7: 106.6 | Q7: 106.9 | R7: 106 | S7: 106.8 | T7: 139.2561 | U7: 106 | V7: 105.2 | W7: 104.5 | X7: 104.5 | Y7: 104.2 | Z7: 103.6 | AA7: 103.9 | AB7: 105.7 | AC7: 104.4 | AD7: 105.3
A8: Rural | B8: 2013 | C8: March | D8: 110.2 | E8: 108.8 | F8: 109.9 | G8: 105.6 | H8: 106.2 | I8: 105.7 | J8: 101.4 | K8: 105.7 | L8: 105 | M8: 103.3 | N8: 105.6 | O8: 108.2 | P8: 106.6 | Q8: 107.6 | R8: 106.8 | S8: 107.5 | T8: 139.2561 | U8: 106.1 | V8: 105.6 | W8: 104.7 | X8: 104.3 | Y8: 104.6 | Z8: 104 | AA8: 104.3 | AB8: 106.5 | AC8: 104.6 | AD8: 106
A9: Urban | B9: 2013 | C9: March | D9: 113.9 | E9: 111.4 | F9: 113.2 | G9: 104.3 | H9: 102.7 | I9: 104.9 | J9: 103.8 | K9: 103.5 | L9: 102.6 | M9: 102.4 | N9: 107 | O9: 109.8 | P9: 107.3 | Q9: 107.2 | R9: 106 | S9: 107 | T9: 139.2561 | U9: 106 | V9: 105.7 | W9: 105.2 | X9: 104.2 | Y9: 105.5 | Z9: 103.5 | AA9: 103.8 | AB9: 106.8 | AC9: 104.9 | AD9: 105
A10: Rural+Urban | B10: 2013 | C10: March | D10: 111.4 | E10: 109.7 | F10: 111.2 | G10: 105.1 | H10: 104.9 | I10: 105.3 | J10: 102.2 | K10: 105 | L10: 104.2 | M10: 103 | N10: 106.2 | O10: 108.9 | P10: 106.9 | Q10: 107.4 | R10: 106.5 | S10: 107.3 | T10: 139.2561 | U10: 106.1 | V10: 105.6 | W10: 104.9 | X10: 104.3 | Y10: 105.1 | Z10: 103.7 | AA10: 104 | AB10: 106.6 | AC10: 104.7 | AD10: 105.5
A11: Rural | B11: 2013 | C11: April | D11: 110.2 | E11: 109.5 | F11: 106.9 | G11: 106.3 | H11: 105.7 | I11: 108.3 | J11: 103.4 | K11: 105.7 | L11: 104.2 | M11: 103.2 | N11: 106.5 | O11: 108.8 | P11: 107.1 | Q11: 108.1 | R11: 107.4 | S11: 108 | T11: 139.2561 | U11: 106.5 | V11: 106.1 | W11: 105.1 | X11: 102.7 | Y11: 104.4 | Z11: 104.5 | AA11: 104.8 | AB11: 107.1 | AC11: 104.6 | AD11: 106.4
A12: Urban | B12: 2013 | C12: April | D12: 114.6 | E12: 113.4 | F12: 106 | G12: 104.7 | H12: 102.1 | I12: 109.5 | J12: 109.7 | K12: 104.6 | L12: 102 | M12: 103.5 | N12: 108.2 | O12: 110.6 | P12: 108.8 | Q12: 107.9 | R12: 106.4 | S12: 107.7 | T12: 139.2561 | U12: 106.4 | V12: 106.5 | W12: 105.7 | X12: 103.2 | Y12: 105 | Z12: 104 | AA12: 105.2 | AB12: 108.5 | AC12: 105.1 | AD12: 105.7
A13: Rural+Urban | B13: 2013 | C13: April | D13: 111.6 | E13: 110.9 | F13: 106.6 | G13: 105.7 | H13: 104.4 | I13: 108.9 | J13: 105.5 | K13: 105.3 | L13: 103.5 | M13: 103.3 | N13: 107.2 | O13: 109.6 | P13: 107.7 | Q13: 108 | R13: 107 | S13: 107.9 | T13: 139.2561 | U13: 106.5 | V13: 106.3 | W13: 105.3 | X13: 102.9 | Y13: 104.7 | Z13: 104.2 | AA13: 105 | AB13: 107.5 | AC13: 104.8 | AD13: 106.1
... A259: Rural+Urban | B259: 2020 | C259: March | D259: 145.1 | E259: 167 | F259: 148.1 | G259: 151.5 | H259: 131.2 | I259: 142.5 | J259: 157.3 | K259: 141.1 | L259: 113.2 | M259: 153.2 | N259: 136.7 | O259: 159.6 | P259: 148.9 | Q259: 151.2 | R259: 141.9 | S259: 149.8 | T259: 139.2561 | U259: 148.9 | V259: 146.4 | W259: 152.3 | X259: 145.2 | Y259: 129.9 | Z259: 143.7 | AA259: 156.1 | AB259: 171.2 | AC259: 143.8 | AD259: 148.6
A260: Rural | B260: 2020 | C260: April | D260: 147.2 | E260: 156.26475 | F260: 146.9 | G260: 155.6 | H260: 137.1 | I260: 147.3 | J260: 162.7 | K260: 150.2 | L260: 119.8 | M260: 158.7 | N260: 139.2 | O260: 149.08716 | P260: 150.1 | Q260: 142.66366 | R260: 133.1 | S260: 141.67432 | T260: 139.2561 | U260: 148.4 | V260: 136.68689 | W260: 154.3 | X260: 127.65 | Y260: 119.7 | Z260: 129.85 | AA260: 141.13115 | AB260: 155.38579 | AC260: 129.65 | AD260: NA
A261: Urban | B261: 2020 | C261: April | D261: 151.8 | E261: 156.26475 | F261: 151.9 | G261: 155.5 | H261: 131.6 | I261: 152.9 | J261: 180 | K261: 150.8 | L261: 121.2 | M261: 154 | N261: 133.5 | O261: 149.08716 | P261: 153.5 | Q261: 142.66366 | R261: 133.1 | S261: 141.67432 | T261: 139.2561 | U261: 137.1 | V261: 136.68689 | W261: 144.8 | X261: 127.65 | Y261: 119.7 | Z261: 129.85 | AA261: 141.13115 | AB261: 155.38579 | AC261: 129.65 | AD261: NA
A262: Rural+Urban | B262: 2020 | C262: April | D262: 148.7 | E262: 156.26475 | F262: 148.8 | G262: 155.6 | H262: 135.1 | I262: 149.9 | J262: 168.6 | K262: 150.4 | L262: 120.3 | M262: 157.1 | N262: 136.8 | O262: 149.08716 | P262: 151.4 | Q262: 142.66366 | R262: 133.1 | S262: 141.67432 | T262: 139.2561 | U262: 144.1 | V262: 136.68689 | W262: 150.7 | X262: 127.65 | Y262: 119.7 | Z262: 129.85 | AA262: 141.13115 | AB262: 155.38579 | AC262: 129.65 | AD262: NA
A263: Rural | B263: 2020 | C263: May | D263: 136.68591 | E263: 156.26475 | F263: 135.5 | G263: NA | H263: 120.5 | I263: 140.84092 | J263: 155.75203 | K263: 141.43089 | L263: 110.92493 | M263: 139.5 | N263: 129 | O263: 149.08716 | P263: 138.6 | Q263: 142.66366 | R263: 133.1 | S263: 141.67432 | T263: 139.2561 | U263: 132.2 | V263: 136.68689 | W263: 133.6 | X263: 127.65 | Y263: 119.7 | Z263: 129.85 | AA263: 141.13115 | AB263: 155.38579 | AC263: 129.65 | AD263: NA
A264: Urban | B264: 2020 | C264: May | D264: 136.68591 | E264: 156.26475 | F264: 135.5 | G264: NA | H264: 120.5 | I264: 140.84092 | J264: 155.75203 | K264: 141.43089 | L264: 110.92493 | M264: 139.5 | N264: 129 | O264: 149.08716 | P264: 138.6 | Q264: 142.66366 | R264: 133.1 | S264: 141.67432 | T264: 139.2561 | U264: 132.2 | V264: 136.68689 | W264: 133.6 | X264: 127.65 | Y264: 119.7 | Z264: 129.85 | AA264: 141.13115 | AB264: 155.38579 | AC264: 129.65 | AD264: NA
A265: Rural+Urban | B265: 2020 | C265: May | D265: 136.68591 | E265: 156.26475 | F265: 135.5 | G265: NA | H265: 120.5 | I265: 140.84092 | J265: 155.75203 | K265: 141.43089 | L265: 110.92493 | M265: 139.5 | N265: 129 | O265: 149.08716 | P265: 138.6 | Q265: 142.66366 | R265: 133.1 | S265: 141.67432 | T265: 139.2561 | U265: 132.2 | V265: 136.68689 | W265: 133.6 | X265: 127.65 | Y265: 119.7 | Z265: 129.85 | AA265: 141.13115 | AB265: 155.38579 | AC265: 129.65 | AD265: NA
A266: Rural | B266: 2020 | C266: June | D266: 136.68591 | E266: 156.26475 | F266: 135.5 | G266: 153.3 | H266: 120.5 | I266: 140.84092 | J266: 155.75203 | K266: 141.43089 | L266: 110.92493 | M266: 139.5 | N266: 129 | O266: 149.08716 | P266: 138.6 | Q266: 154.7 | R266: 133.1 | S266: 141.67432 | T266: 139.2561 | U266: 132.2 | V266: 136.68689 | W266: 133.6 | X266: 127.65 | Y266: 119.7 | Z266: 129.85 | AA266: 141.13115 | AB266: 155.38579 | AC266: 129.65 | AD266: 152.7
A267: Urban | B267: 2020 | C267: June | D267: 136.68591 | E267: 156.26475 | F267: 135.5 | G267: 153.4 | H267: 120.5 | I267: 140.84092 | J267: 155.75203 | K267: 141.43089 | L267: 110.92493 | M267: 139.5 | N267: 129 | O267: 149.08716 | P267: 138.6 | Q267: 149.1 | R267: 133.1 | S267: 141.67432 | T267: 139.2561 | U267: 132.2 | V267: 136.68689 | W267: 133.6 | X267: 127.65 | Y267: 119.7 | Z267: 129.85 | AA267: 141.13115 | AB267: 155.38579 | AC267: 129.65 | AD267: 150.8
A268: Rural+Urban | B268: 2020 | C268: June | D268: 136.68591 | E268: 156.26475 | F268: 135.5 | G268: 153.3 | H268: 120.5 | I268: 140.84092 | J268: 155.75203 | K268: 141.43089 | L268: 110.92493 | M268: 139.5 | N268: 129 | O268: 149.08716 | P268: 138.6 | Q268: 152.5 | R268: 133.1 | S268: 141.67432 | T268: 139.2561 | U268: 132.2 | V268: 136.68689 | W268: 133.6 | X268: 127.65 | Y268: 119.7 | Z268: 129.85 | AA268: 141.13115 | AB268: 155.38579 | AC268: 129.65 | AD268: 151.8
A269: Rural | B269: 2020 | C269: July | D269: 136.68591 | E269: 156.26475 | F269: 135.5 | G269: 153.3 | H269: 120.5 | I269: 140.84092 | J269: 155.75203 | K269: 141.43089 | L269: 110.92493 | M269: 139.5 | N269: 129 | O269: 149.08716 | P269: 138.6 | Q269: 154.7 | R269: 133.1 | S269: 141.67432 | T269: 139.2561 | U269: 132.2 | V269: 136.68689 | W269: 133.6 | X269: 127.65 | Y269: 119.7 | Z269: 129.85 | AA269: 141.13115 | AB269: 155.38579 | AC269: 129.65 | AD269: 152.7
A270: Urban | B270: 2020 | C270: July | D270: 136.68591 | E270: 156.26475 | F270: 135.5 | G270: 153.4 | H270: 120.5 | I270: 140.84092 | J270: 155.75203 | K270: 141.43089 | L270: 110.92493 | M270: 139.5 | N270: 129 | O270: 149.08716 | P270: 138.6 | Q270: 149.1 | R270: 133.1 | S270: 141.67432 | T270: 139.2561 | U270: 132.2 | V270: 136.68689 | W270: 133.6 | X270: 127.65 | Y270: 119.7 | Z270: 129.85 | AA270: 141.13115 | AB270: 155.38579 | AC270: 129.65 | AD270: 150.8
A271: Rural+Urban | B271: 2020 | C271: July | D271: 136.68591 | E271: 156.26475 | F271: 135.5 | G271: 153.3 | H271: 120.5 | I271: 140.84092 | J271: 155.75203 | K271: 141.43089 | L271: 110.92493 | M271: 139.5 | N271: 129 | O271: 149.08716 | P271: 138.6 | Q271: 152.5 | R271: 133.1 | S271: 141.67432 | T271: 139.2561 | U271: 132.2 | V271: 136.68689 | W271: 133.6 | X271: 127.65 | Y271: 119.7 | Z271: 129.85 | AA271: 141.13115 | AB271: 155.38579 | AC271: 129.65 | AD271: 151.8
A272: Rural | B272: 2020 | C272: August | D272: 136.68591 | E272: 156.26475 | F272: 135.5 | G272: 153.3 | H272: 120.5 | I272: 140.84092 | J272: 155.75203 | K272: 141.43089 | L272: 110.92493 | M272: 139.5 | N272: 129 | O272: 149.08716 | P272: 138.6 | Q272: 155.1 | R272: 133.1 | S272: 141.67432 | T272: 139.2561 | U272: 132.2 | V272: 136.68689 | W272: 133.6 | X272: 127.65 | Y272: 119.7 | Z272: 129.85 | AA272: 141.13115 | AB272: 155.38579 | AC272: 129.65 | AD272: 154.7
A273: Urban | B273: 2020 | C273: August | D273: 136.68591 | E273: 156.26475 | F273: 135.5 | G273: 153.4 | H273: 120.5 | I273: 140.84092 | J273: 155.75203 | K273: 141.43089 | L273: 110.92493 | M273: 139.5 | N273: 129 | O273: 149.08716 | P273: 138.6 | Q273: 150 | R273: 133.1 | S273: 141.67432 | T273: 139.2561 | U273: 132.2 | V273: 136.68689 | W273: 133.6 | X273: 127.65 | Y273: 119.7 | Z273: 129.85 | AA273: 141.13115 | AB273: 155.38579 | AC273: 129.65 | AD273: 152.9
A274: Rural+Urban | B274: 2020 | C274: August | D274: 136.68591 | E274: 156.26475 | F274: 135.5 | G274: 153.3 | H274: 120.5 | I274: 140.84092 | J274: 155.75203 | K274: 141.43089 | L274: 110.92493 | M274: 139.5 | N274: 129 | O274: 149.08716 | P274: 138.6 | Q274: 153.1 | R274: 133.1 | S274: 141.67432 | T274: 139.2561 | U274: 132.2 | V274: 136.68689 | W274: 133.6 | X274: 127.65 | Y274: 119.7 | Z274: 129.85 | AA274: 141.13115 | AB274: 155.38579 | AC274: 129.65 | AD274: 153.9
A275: Rural | B275: 2020 | C275: September | D275: 136.68591 | E275: 156.26475 | F275: 135.5 | G275: 153.4 | H275: 120.5 | I275: 140.84092 | J275: 155.75203 | K275: 141.43089 | L275: 110.92493 | M275: 139.5 | N275: 129 | O275: 149.08716 | P275: 138.6 | Q275: 155.4 | R275: 133.1 | S275: 141.67432 | T275: 139.2561 | U275: 132.2 | V275: 136.68689 | W275: 133.6 | X275: 127.65 | Y275: 119.7 | Z275: 129.85 | AA275: 141.13115 | AB275: 155.38579 | AC275: 129.65 | AD275: 155.4
A276: Urban | B276: 2020 | C276: September | D276: 136.68591 | E276: 156.26475 | F276: 135.5 | G276: 153.9 | H276: 120.5 | I276: 140.84092 | J276: 155.75203 | K276: 141.43089 | L276: 110.92493 | M276: 139.5 | N276: 129 | O276: 149.08716 | P276: 138.6 | Q276: 150.2 | R276: 133.1 | S276: 141.67432 | T276: 139.2561 | U276: 132.2 | V276: 136.68689 | W276: 133.6 | X276: 127.65 | Y276: 119.7 | Z276: 129.85 | AA276: 141.13115 | AB276: 155.38579 | AC276: 129.65 | AD276: 154
A277: Rural+Urban | B277: 2020 | C277: September | D277: 136.68591 | E277: 156.26475 | F277: 135.5 | G277: 153.6 | H277: 120.5 | I277: 140.84092 | J277: 155.75203 | K277: 141.43089 | L277: 110.92493 | M277: 139.5 | N277: 129 | O277: 149.08716 | P277: 138.6 | Q277: 153.4 | R277: 133.1 | S277: 141.67432 | T277: 139.2561 | U277: 132.2 | V277: 136.68689 | W277: 133.6 | X277: 127.65 | Y277: 119.7 | Z277: 129.85 | AA277: 141.13115 | AB277: 155.38579 | AC277: 129.65 | AD277: 154.7
... A373: Rural+Urban | B373: 2023 | C373: May | D373: 136.68591 | E373: 156.26475 | F373: 135.5 | G373: 179.5 | H373: 120.5 | I373: 140.84092 | J373: 155.75203 | K373: 141.43089 | L373: 110.92493 | M373: 139.5 | N373: 129 | O373: 149.08716 | P373: 138.6 | Q373: 187.3 | R373: 133.1 | S373: 141.67432 | T373: 175.6 | U373: 132.2 | V373: 136.68689 | W373: 133.6 | X373: 127.65 | Y373: 119.7 | Z373: 129.85 | AA373: 141.13115 | AB373: 155.38579 | AC373: 129.65 | AD373: 179.1
D374: 136.68591 | E374: 156.26475 | F374: 135.5 | H374: 120.5 | I374: 140.84092 | J374: 155.75203 | K374: 141.43089 | L374: 110.92493 | M374: 139.5 | N374: 129 | O374: 149.08716 | P374: 138.6 | Q374: 142.66366 | R374: 133.1 | S374: 141.67432 | T374: 139.26 | U374: 132.2 | V374: 136.68689 | W374: 133.6 | X374: 127.65 | Y374: 119.7 | Z374: 129.85 | AA374: 141.13115 | AB374: 155.38579 | AC374: 129.65
D375: 136.68591 | E375: 156.26475 | F375: 135.5 | H375: 120.5 | I375: 140.84092 | J375: 155.75203 | K375: 141.43089 | L375: 110.92493 | M375: 139.5 | N375: 129 | O375: 149.08716 | P375: 138.6 | Q375: 142.66366 | R375: 133.1 | S375: 141.67432 | T375: 139.26 | U375: 132.2 | V375: 136.68689 | W375: 133.6 | X375: 127.65 | Y375: 119.7 | Z375: 129.85 | AA375: 141.13115 | AB375: 155.38579 | AC375: 129.65

Sheet Problem Sheet
A1: Problem Statement:
A3: You are working with the National Statistical Office which is equipped to release inflation numbers in India. As an analyst, you are provided with CPI data and are equipped to find out insights from the data. Your senior wants you to find key trends and deep dive into the data to answer the following questions -
A5: 1. Based on the latest month’s data, identify the contribution of different broader categories (food, energy, transportation, education, etc.) towards the CPI basket. Broader categories (buckets) can be created by combining similar categories into one bucket; Ex.: Meals, Beverages, Cereals, can be clubbed to create “Food” category, etc.
A6: Contribution to CPI (Latest Month)
A9: Which broader category has the highest contribution towards CPI calculation
A11: Contribution is calculated by evaluating the underlying index values for broader category and should add to 100% when contribution from different broader categories are added.
A15: 2. A trend of Y-o-Y increase in CPI (rural + urban) inflation starting 2017 for the entire basket of products combined.
A17: YoY CPI Inflation - 2017 Onwards
A19: Create a graph depicting the growth rate Y-o-Y and identify the year with highest inflation rate
A21: Highlight the reason why the year has the highest inflation (based on research).
A25: 3. With India's retail inflation reaching a 3-month high of 5.55% in November 2023, largely due to a sharp rise in food prices. Analyze the following for 12 months ending May’23
A27: Month-on-Month CPI: Food Products (June,22-May,23)
... A47: CPI Inflation : Crude Oil CPI Influence

Sheet Sheet1
A1: Year | B1: Vegetables
A2: {=_xlfn.UNIQUE('Main Data'!B3:B374)} -> 2013
A3: 2014 | C3: John28 Sunil34 Meera30 Arjun41 Neha25
A4: 2015 | F4: >=30 | G4: Snr | H4: else jnr
A5: 2016 | C5: Name | D5: Age | E5: Conact
A6: 2017 | C6: John | D6: 28 | E6: =_xlfn.CONCAT(C6,"(",IF(D6>=30,"Senior","Junior"),")") -> John(Junior)
A7: 2018 | C7: Sunil | D7: 34 | E7: =_xlfn.CONCAT(C7,"(",IF(D7>=30,"Senior","Junior"),")") -> Sunil(Senior)
A8: 2019 | C8: Meera | D8: 30 | E8: =_xlfn.CONCAT(C8,"(",IF(D8>=30,"Senior","Junior"),")") -> Meera(Senior)
A9: 2020 | C9: Arjun | D9: 41 | E9: =_xlfn.CONCAT(C9,"(",IF(D9>=30,"Senior","Junior"),")") -> Arjun(Senior)
A10: 2021 | C10: Neha | D10: 25 | E10: =_xlfn.CONCAT(C10,"(",IF(D10>=30,"Senior","Junior"),")") -> Neha(Junior)
A11: 2022
A12: 2023

Sheet Main Data
A1: INFO | E1: Food Products | S1: Clothing & Misc | W1: Housing & Misc | AA1: Health and personal Care | AD1: Transport and communication | AE1: Education and Entertainment | AH1: Miscellaneuos | AK1: General
A2: Sector | B2: Year | C2: Month | D2: Yes/No | E2: Cereals and products | F2: Meat and fish | G2: Egg | H2: Milk and products | I2: Oils and fats | J2: Fruits | K2: Vegetables | L2: Pulses and products | M2: Sugar and Confectionery | N2: Spices | O2: Non-alcoholic beverages | P2: Prepared meals, snacks, sweets etc. | Q2: Food and beverages | R2: Total (Food Products) | S2: Clothing | T2: Footwear | U2: Clothing and footwear | V2: Total (Clothing & MISC) | W2: Housing | X2: Fuel and light | Y2: Household goods and services | Z2: Total (Housing & MISC) | AA2: Health | AB2: Personal care and effects | AC2: Total (Health & Personal Care) | AD2: Transport and communication | AE2: Recreation and amusement | AF2: Education | AG2: Total Edu & Ent | AH2: Pan, tobacco and intoxicants | AI2: Miscellaneous | AJ2: Total (MISC) | AK2: General index
A3: Rural | B3: 2013 | C3: January | D3: =IF(H3>120,IF(M3>120,"Yes","No"),"No") -> No | E3: 107.5 | F3: 106.3 | G3: 108.1 | H3: 104.9 | I3: 106.1 | J3: 103.9 | K3: 101.9 | L3: 106.1 | M3: 106.8 | N3: 103.1 | O3: 104.8 | P3: 106.7 | Q3: 105.5 | R3: =SUM(E3:Q3) -> 1371.7 | S3: 106.5 | T3: 105.8 | U3: 106.4 | V3: =SUM(S3:U3) -> 318.7 | W3: 139.25 | X3: 105.5 | Y3: 104.8 | Z3: =SUM(W3:Y3) -> 349.55 | AA3: 104 | AB3: 104.7 | AC3: =SUM(AA3:AB3) -> 208.7 | AD3: 103.3 | AE3: 103.4 | AF3: 103.8 | AG3: =SUM(AE3:AF3) -> 207.2 | AH3: 105.1 | AI3: 104 | AJ3: =SUM(AH3:AI3) -> 209.1 | AK3: 105.1
A4: Urban | B4: 2013 | C4: January | D4: =IF(H4>120,IF(M4>120,"Yes","No"),"No") -> No | E4: 110.5 | F4: 109.1 | G4: 113 | H4: 103.6 | I4: 103.4 | J4: 102.3 | K4: 102.9 | L4: 105.8 | M4: 105.1 | N4: 101.8 | O4: 105.1 | P4: 107.9 | Q4: 105.9 | R4: =SUM(E4:Q4) -> 1376.4 | S4: 105.9 | T4: 105 | U4: 105.8 | V4: =SUM(S4:U4) -> 316.7 | W4: 100.3 | X4: 105.4 | Y4: 104.8 | Z4: =SUM(W4:Y4) -> 310.5 | AA4: 104.1 | AB4: 104.3 | AC4: =SUM(AA4:AB4) -> 208.4 | AD4: 103.2 | AE4: 102.9 | AF4: 103.5 | AG4: =SUM(AE4:AF4) -> 206.4 | AH4: 105.2 | AI4: 103.7 | AJ4: =SUM(AH4:AI4) -> 208.9 | AK4: 104
A5: Rural+Urban | B5: 2013 | C5: January | D5: =IF(H5>120,IF(M5>120,"Yes","No"),"No") -> No | E5: 108.4 | F5: 107.3 | G5: 110 | H5: 104.4 | I5: 105.1 | J5: 103.2 | K5: 102.2 | L5: 106 | M5: 106.2 | N5: 102.7 | O5: 104.9 | P5: 107.3 | Q5: 105.6 | R5: =SUM(E5:Q5) -> 1373.3 | S5: 106.3 | T5: 105.5 | U5: 106.2 | V5: =SUM(S5:U5) -> 318 | W5: 100.3 | X5: 105.5 | Y5: 104.8 | Z5: =SUM(W5:Y5) -> 310.6 | AA5: 104 | AB5: 104.5 | AC5: =SUM(AA5:AB5) -> 208.5 | AD5: 103.2 | AE5: 103.1 | AF5: 103.6 | AG5: =SUM(AE5:AF5) -> 206.7 | AH5: 105.1 | AI5: 103.9 | AJ5: =SUM(AH5:AI5) -> 209 | AK5: 104.6
A6: Rural | B6: 2013 | C6: February | D6: =IF(H6>120,IF(M6>120,"Yes","No"),"No") -> No | E6: 109.2 | F6: 108.7 | G6: 110.2 | H6: 105.4 | I6: 106.7 | J6: 104 | K6: 102.4 | L6: 105.9 | M6: 105.7 | N6: 103.1 | O6: 105.1 | P6: 107.7 | Q6: 106.3 | R6: =SUM(E6:Q6) -> 1380.4 | S6: 107.1 | T6: 106.3 | U6: 107 | V6: =SUM(S6:U6) -> 320.4 | W6: 139.25 | X6: 106.2 | Y6: 105.2 | Z6: =SUM(W6:Y6) -> 350.65 | AA6: 104.4 | AB6: 104.6 | AC6: =SUM(AA6:AB6) -> 209 | AD6: 103.9 | AE6: 104 | AF6: 104.1 | AG6: =SUM(AE6:AF6) -> 208.1 | AH6: 105.6 | AI6: 104.4 | AJ6: =SUM(AH6:AI6) -> 210 | AK6: 105.8
A7: Urban | B7: 2013 | C7: February | D7: =IF(H7>120,IF(M7>120,"Yes","No"),"No") -> No | E7: 112.9 | F7: 112.9 | G7: 116.9 | H7: 104 | I7: 103.5 | J7: 103.1 | K7: 104.9 | L7: 104.1 | M7: 103.8 | N7: 102.3 | O7: 106 | P7: 109 | Q7: 107.2 | R7: =SUM(E7:Q7) -> 1390.6 | S7: 106.6 | T7: 105.5 | U7: 106.4 | V7: =SUM(S7:U7) -> 318.5 | W7: 100.4 | X7: 105.7 | Y7: 105.2 | Z7: =SUM(W7:Y7) -> 311.3 | AA7: 104.7 | AB7: 104.3 | AC7: =SUM(AA7:AB7) -> 209 | AD7: 104.4 | AE7: 103.3 | AF7: 103.7 | AG7: =SUM(AE7:AF7) -> 207 | AH7: 106 | AI7: 104.3 | AJ7: =SUM(AH7:AI7) -> 210.3 | AK7: 104.7
A8: Rural+Urban | B8: 2013 | C8: February | D8: =IF(H8>120,IF(M8>120,"Yes","No"),"No") -> No | E8: 110.4 | F8: 110.2 | G8: 112.8 | H8: 104.9 | I8: 105.5 | J8: 103.6 | K8: 103.2 | L8: 105.3 | M8: 105.1 | N8: 102.8 | O8: 105.5 | P8: 108.3 | Q8: 106.6 | R8: =SUM(E8:Q8) -> 1384.2 | S8: 106.9 | T8: 106 | U8: 106.8 | V8: =SUM(S8:U8) -> 319.7 | W8: 100.4 | X8: 106 | Y8: 105.2 | Z8: =SUM(W8:Y8) -> 311.6 | AA8: 104.5 | AB8: 104.5 | AC8: =SUM(AA8:AB8) -> 209 | AD8: 104.2 | AE8: 103.6 | AF8: 103.9 | AG8: =SUM(AE8:AF8) -> 207.5 | AH8: 105.7 | AI8: 104.4 | AJ8: =SUM(AH8:AI8) -> 210.1 | AK8: 105.3
A9: Rural | B9: 2013 | C9: March | D9: =IF(H9>120,IF(M9>120,"Yes","No"),"No") -> No | E9: 110.2 | F9: 108.8 | G9: 109.9 | H9: 105.6 | I9: 106.2 | J9: 105.7 | K9: 101.4 | L9: 105.7 | M9: 105 | N9: 103.3 | O9: 105.6 | P9: 108.2 | Q9: 106.6 | R9: =SUM(E9:Q9) -> 1382.2 | S9: 107.6 | T9: 106.8 | U9: 107.5 | V9: =SUM(S9:U9) -> 321.9 | W9: 139.25 | X9: 106.1 | Y9: 105.6 | Z9: =SUM(W9:Y9) -> 350.95 | AA9: 104.7 | AB9: 104.3 | AC9: =SUM(AA9:AB9) -> 209 | AD9: 104.6 | AE9: 104 | AF9: 104.3 | AG9: =SUM(AE9:AF9) -> 208.3 | AH9: 106.5 | AI9: 104.6 | AJ9: =SUM(AH9:AI9) -> 211.1 | AK9: 106
A10: Urban | B10: 2013 | C10: March | D10: =IF(H10>120,IF(M10>120,"Yes","No"),"No") -> No | E10: 113.9 | F10: 111.4 | G10: 113.2 | H10: 104.3 | I10: 102.7 | J10: 104.9 | K10: 103.8 | L10: 103.5 | M10: 102.6 | N10: 102.4 | O10: 107 | P10: 109.8 | Q10: 107.3 | R10: =SUM(E10:Q10) -> 1386.8 | S10: 107.2 | T10: 106 | U10: 107 | V10: =SUM(S10:U10) -> 320.2 | W10: 100.4 | X10: 106 | Y10: 105.7 | Z10: =SUM(W10:Y10) -> 312.1 | AA10: 105.2 | AB10: 104.2 | AC10: =SUM(AA10:AB10) -> 209.4 | AD10: 105.5 | AE10: 103.5 | AF10: 103.8 | AG10: =SUM(AE10:AF10) -> 207.3 | AH10: 106.8 | AI10: 104.9 | AJ10: =SUM(AH10:AI10) -> 211.7 | AK10: 105
A11: Rural+Urban | B11: 2013 | C11: March | D11: =IF(H11>120,IF(M11>120,"Yes","No"),"No") -> No | E11: 111.4 | F11: 109.7 | G11: 111.2 | H11: 105.1 | I11: 104.9 | J11: 105.3 | K11: 102.2 | L11: 105 | M11: 104.2 | N11: 103 | O11: 106.2 | P11: 108.9 | Q11: 106.9 | R11: =SUM(E11:Q11) -> 1384 | S11: 107.4 | T11: 106.5 | U11: 107.3 | V11: =SUM(S11:U11) -> 321.2 | W11: 100.4 | X11: 106.1 | Y11: 105.6 | Z11: =SUM(W11:Y11) -> 312.1 | AA11: 104.9 | AB11: 104.3 | AC11: =SUM(AA11:AB11) -> 209.2 | AD11: 105.1 | AE11: 103.7 | AF11: 104 | AG11: =SUM(AE11:AF11) -> 207.7 | AH11: 106.6 | AI11: 104.7 | AJ11: =SUM(AH11:AI11) -> 211.3 | AK11: 105.5
A12: Rural | B12: 2013 | C12: April | D12: =IF(H12>120,IF(M12>120,"Yes","No"),"No") -> No | E12: 110.2 | F12: 109.5 | G12: 106.9 | H12: 106.3 | I12: 105.7 | J12: 108.3 | K12: 103.4 | L12: 105.7 | M12: 104.2 | N12: 103.2 | O12: 106.5 | P12: 108.8 | Q12: 107.1 | R12: =SUM(E12:Q12) -> 1385.8 | S12: 108.1 | T12: 107.4 | U12: 108 | V12: =SUM(S12:U12) -> 323.5 | W12: 139.25 | X12: 106.5 | Y12: 106.1 | Z12: =SUM(W12:Y12) -> 351.85 | AA12: 105.1 | AB12: 102.7 | AC12: =SUM(AA12:AB12) -> 207.8 | AD12: 104.4 | AE12: 104.5 | AF12: 104.8 | AG12: =SUM(AE12:AF12) -> 209.3 | AH12: 107.1 | AI12: 104.6 | AJ12: =SUM(AH12:AI12) -> 211.7 | AK12: 106.4
A13: Urban | B13: 2013 | C13: April | D13: =IF(H13>120,IF(M13>120,"Yes","No"),"No") -> No | E13: 114.6 | F13: 113.4 | G13: 106 | H13: 104.7 | I13: 102.1 | J13: 109.5 | K13: 109.7 | L13: 104.6 | M13: 102 | N13: 103.5 | O13: 108.2 | P13: 110.6 | Q13: 108.8 | R13: =SUM(E13:Q13) -> 1397.7 | S13: 107.9 | T13: 106.4 | U13: 107.7 | V13: =SUM(S13:U13) -> 322 | W13: 100.5 | X13: 106.4 | Y13: 106.5 | Z13: =SUM(W13:Y13) -> 313.4 | AA13: 105.7 | AB13: 103.2 | AC13: =SUM(AA13:AB13) -> 208.9 | AD13: 105 | AE13: 104 | AF13: 105.2 | AG13: =SUM(AE13:AF13) -> 209.2 | AH13: 108.5 | AI13: 105.1 | AJ13: =SUM(AH13:AI13) -> 213.6 | AK13: 105.7
A14: Rural+Urban | B14: 2013 | C14: April | D14: =IF(H14>120,IF(M14>120,"Yes","No"),"No") -> No | E14: 111.6 | F14: 110.9 | G14: 106.6 | H14: 105.7 | I14: 104.4 | J14: 108.9 | K14: 105.5 | L14: 105.3 | M14: 103.5 | N14: 103.3 | O14: 107.2 | P14: 109.6 | Q14: 107.7 | R14: =SUM(E14:Q14) -> 1390.2 | S14: 108 | T14: 107 | U14: 107.9 | V14: =SUM(S14:U14) -> 322.9 | W14: 100.5 | X14: 106.5 | Y14: 106.3 | Z14: =SUM(W14:Y14) -> 313.3 | AA14: 105.3 | AB14: 102.9 | AC14: =SUM(AA14:AB14) -> 208.2 | AD14: 104.7 | AE14: 104.2 | AF14: 105 | AG14: =SUM(AE14:AF14) -> 209.2 | AH14: 107.5 | AI14: 104.8 | AJ14: =SUM(AH14:AI14) -> 212.3 | AK14: 106.1
... A260: Rural+Urban | B260: 2020 | C260: March | D260: =IF(H260>120,IF(M260>120,"Yes","No"),"No") -> No | E260: 145.1 | F260: 167 | G260: 148.1 | H260: 151.5 | I260: 131.2 | J260: 142.5 | K260: 157.3 | L260: 141.1 | M260: 113.2 | N260: 153.2 | O260: 136.7 | P260: 159.6 | Q260: 148.9 | R260: =SUM(E260:Q260) -> 1895.4 | S260: 151.2 | T260: 141.9 | U260: 149.8 | V260: =SUM(S260:U260) -> 442.9 | W260: 154.5 | X260: 148.9 | Y260: 146.4 | Z260: =SUM(W260:Y260) -> 449.8 | AA260: 152.3 | AB260: 145.2 | AC260: =SUM(AA260:AB260) -> 297.5 | AD260: 129.9 | AE260: 143.7 | AF260: 156.1 | AG260: =SUM(AE260:AF260) -> 299.8 | AH260: 171.2 | AI260: 143.8 | AJ260: =SUM(AH260:AI260) -> 315 | AK260: 148.6
A261: Rural | B261: 2020 | C261: April | D261: =IF(H261>120,IF(M261>120,"Yes","No"),"No") -> No | E261: 147.2 | F261: NA | G261: 146.9 | H261: 155.6 | I261: 137.1 | J261: 147.3 | K261: 162.7 | L261: 150.2 | M261: 119.8 | N261: 158.7 | O261: 139.2 | P261: NA | Q261: 150.1 | R261: NA | S261: NA | T261: NA | U261: NA | V261: NA | W261: 139.25 | X261: 148.4 | Y261: NA | Z261: NA | AA261: 154.3 | AB261: NA | AC261: NA | AD261: NA | AE261: NA | AF261: NA | AG261: NA | AH261: NA | AI261: NA | AJ261: NA | AK261: NA
A262: Urban | B262: 2020 | C262: April | D262: =IF(H262>120,IF(M262>120,"Yes","No"),"No") -> Yes | E262: 151.8 | F262: NA | G262: 151.9 | H262: 155.5 | I262: 131.6 | J262: 152.9 | K262: 180 | L262: 150.8 | M262: 121.2 | N262: 154 | O262: 133.5 | P262: NA | Q262: 153.5 | R262: NA | S262: NA | T262: NA | U262: NA | V262: NA | W262: 155.6 | X262: 137.1 | Y262: NA | Z262: NA | AA262: 144.8 | AB262: NA | AC262: NA | AD262: NA | AE262: NA | AF262: NA | AG262: NA | AH262: NA | AI262: NA | AJ262: NA | AK262: NA
A263: Rural+Urban | B263: 2020 | C263: April | D263: =IF(H263>120,IF(M263>120,"Yes","No"),"No") -> Yes | E263: 148.7 | F263: NA | G263: 148.8 | H263: 155.6 | I263: 135.1 | J263: 149.9 | K263: 168.6 | L263: 150.4 | M263: 120.3 | N263: 157.1 | O263: 136.8 | P263: NA | Q263: 151.4 | R263: NA | S263: NA | T263: NA | U263: NA | V263: NA | W263: 155.6 | X263: 144.1 | Y263: NA | Z263: NA | AA263: 150.7 | AB263: NA | AC263: NA | AD263: NA | AE263: NA | AF263: NA | AG263: NA | AH263: NA | AI263: NA | AJ263: NA | AK263: NA
A264: Rural | B264: 2020 | C264: May | D264: =IF(H264>120,IF(M264>120,"Yes","No"),"No") -> Yes | E264: NA | F264: NA | G264: NA | H264: NA | I264: NA | J264: NA | K264: NA | L264: NA | M264: NA | N264: NA | O264: NA | P264: NA | Q264: NA | R264: NA | S264: NA | T264: NA | U264: NA | V264: NA | W264: 139.25 | X264: NA | Y264: NA | Z264: NA | AA264: NA | AB264: NA | AC264: NA | AD264: NA | AE264: NA | AF264: NA | AG264: NA | AH264: NA | AI264: NA | AJ264: NA | AK264: NA
A265: Urban | B265: 2020 | C265: May | D265: =IF(H265>120,IF(M265>120,"Yes","No"),"No") -> Yes | E265: NA | F265: NA | G265: NA | H265: NA | I265: NA | J265: NA | K265: NA | L265: NA | M265: NA | N265: NA | O265: NA | P265: NA | Q265: NA | R265: NA | S265: NA | T265: NA | U265: NA | V265: NA | W265: 139.25 | X265: NA | Y265: NA | Z265: NA | AA265: NA | AB265: NA | AC265: NA | AD265: NA | AE265: NA | AF265: NA | AG265: NA | AH265: NA | AI265: NA | AJ265: NA | AK265: NA
A266: Rural+Urban | B266: 2020 | C266: May | D266: =IF(H266>120,IF(M266>120,"Yes","No"),"No") -> Yes | E266: NA | F266: NA | G266: NA | H266: NA | I266: NA | J266: NA | K266: NA | L266: NA | M266: NA | N266: NA | O266: NA | P266: NA | Q266: NA | R266: NA | S266: NA | T266: NA | U266: NA | V266: NA | W266: 139.25 | X266: NA | Y266: NA | Z266: NA | AA266: NA | AB266: NA | AC266: NA | AD266: NA | AE266: NA | AF266: NA | AG266: NA | AH266: NA | AI266: NA | AJ266: NA | AK266: NA
A267: Rural | B267: 2020 | C267: June | D267: =IF(H267>120,IF(M267>120,"Yes","No"),"No") -> No | E267: 148.2 | F267: 190.3 | G267: 149.4 | H267: 153.3 | I267: 138.2 | J267: 143.2 | K267: 148.9 | L267: 150.3 | M267: 113.2 | N267: 159.8 | O267: 142.1 | P267: 161.8 | Q267: 152.3 | R267: =SUM(E267:Q267) -> 1951 | S267: 154.7 | T267: 150 | U267: 154.1 | V267: =SUM(S267:U267) -> 458.8 | W267: 139.25 | X267: 144.9 | Y267: 151.7 | Z267: =SUM(W267:Y267) -> 435.85 | AA267: 158.2 | AB267: 151.2 | AC267: =SUM(AA267:AB267) -> 309.4 | AD267: 141.4 | AE267: 153.2 | AF267: 161.8 | AG267: =SUM(AE267:AF267) -> 315 | AH267: 182.4 | AI267: 151.7 | AJ267: =SUM(AH267:AI267) -> 334.1 | AK267: 152.7
A268: Urban | B268: 2020 | C268: June | D268: =IF(H268>120,IF(M268>120,"Yes","No"),"No") -> No | E268: 152.7 | F268: 197 | G268: 154.6 | H268: 153.4 | I268: 132.9 | J268: 151.8 | K268: 171.2 | L268: 152 | M268: 116.3 | N268: 158.8 | O268: 135.6 | P268: 161.7 | Q268: 157 | R268: =SUM(E268:Q268) -> 1995 | S268: 149.1 | T268: 136.6 | U268: 147.2 | V268: =SUM(S268:U268) -> 432.9 | W268: 154.7 | X268: 137.1 | Y268: 140.4 | Z268: =SUM(W268:Y268) -> 432.2 | AA268: 148.1 | AB268: 152.2 | AC268: =SUM(AA268:AB268) -> 300.3 | AD268: 129.3 | AE268: 144.5 | AF268: 152.5 | AG268: =SUM(AE268:AF268) -> 297 | AH268: 186.7 | AI268: 142 | AJ268: =SUM(AH268:AI268) -> 328.7 | AK268: 150.8
A269: Rural+Urban | B269: 2020 | C269: June | D269: =IF(H269>120,IF(M269>120,"Yes","No"),"No") -> No | E269: 149.6 | F269: 192.7 | G269: 151.4 | H269: 153.3 | I269: 136.3 | J269: 147.2 | K269: 156.5 | L269: 150.9 | M269: 114.2 | N269: 159.5 | O269: 139.4 | P269: 161.8 | Q269: 154 | R269: =SUM(E269:Q269) -> 1966.8 | S269: 152.5 | T269: 144.4 | U269: 151.4 | V269: =SUM(S269:U269) -> 448.3 | W269: 154.7 | X269: 141.9 | Y269: 146.4 | Z269: =SUM(W269:Y269) -> 443 | AA269: 154.4 | AB269: 151.6 | AC269: =SUM(AA269:AB269) -> 306 | AD269: 135 | AE269: 148.3 | AF269: 156.4 | AG269: =SUM(AE269:AF269) -> 304.7 | AH269: 183.5 | AI269: 147 | AJ269: =SUM(AH269:AI269) -> 330.5 | AK269: 151.8
A270: Rural | B270: 2020 | C270: July | D270: =IF(H270>120,IF(M270>120,"Yes","No"),"No") -> No | E270: 148.2 | F270: 190.3 | G270: 149.4 | H270: 153.3 | I270: 138.2 | J270: 143.2 | K270: 148.9 | L270: 150.3 | M270: 113.2 | N270: 159.8 | O270: 142.1 | P270: 161.8 | Q270: 152.3 | R270: =SUM(E270:Q270) -> 1951 | S270: 154.7 | T270: 150 | U270: 154.1 | V270: =SUM(S270:U270) -> 458.8 | W270: 139.25 | X270: 144.9 | Y270: 151.7 | Z270: =SUM(W270:Y270) -> 435.85 | AA270: 158.2 | AB270: 151.2 | AC270: =SUM(AA270:AB270) -> 309.4 | AD270: 141.4 | AE270: 153.2 | AF270: 161.8 | AG270: =SUM(AE270:AF270) -> 315 | AH270: 182.4 | AI270: 151.7 | AJ270: =SUM(AH270:AI270) -> 334.1 | AK270: 152.7
A271: Urban | B271: 2020 | C271: July | D271: =IF(H271>120,IF(M271>120,"Yes","No"),"No") -> No | E271: 152.7 | F271: 197 | G271: 154.6 | H271: 153.4 | I271: 132.9 | J271: 151.8 | K271: 171.2 | L271: 152 | M271: 116.3 | N271: 158.8 | O271: 135.6 | P271: 161.7 | Q271: 157 | R271: =SUM(E271:Q271) -> 1995 | S271: 149.1 | T271: 136.6 | U271: 147.2 | V271: =SUM(S271:U271) -> 432.9 | W271: 154.7 | X271: 137.1 | Y271: 140.4 | Z271: =SUM(W271:Y271) -> 432.2 | AA271: 148.1 | AB271: 152.2 | AC271: =SUM(AA271:AB271) -> 300.3 | AD271: 129.3 | AE271: 144.5 | AF271: 152.5 | AG271: =SUM(AE271:AF271) -> 297 | AH271: 186.7 | AI271: 142 | AJ271: =SUM(AH271:AI271) -> 328.7 | AK271: 150.8
A272: Rural+Urban | B272: 2020 | C272: July | D272: =IF(H272>120,IF(M272>120,"Yes","No"),"No") -> No | E272: 149.6 | F272: 192.7 | G272: 151.4 | H272: 153.3 | I272: 136.3 | J272: 147.2 | K272: 156.5 | L272: 150.9 | M272: 114.2 | N272: 159.5 | O272: 139.4 | P272: 161.8 | Q272: 154 | R272: =SUM(E272:Q272) -> 1966.8 | S272: 152.5 | T272: 144.4 | U272: 151.4 | V272: =SUM(S272:U272) -> 448.3 | W272: 154.7 | X272: 141.9 | Y272: 146.4 | Z272: =SUM(W272:Y272) -> 443 | AA272: 154.4 | AB272: 151.6 | AC272: =SUM(AA272:AB272) -> 306 | AD272: 135 | AE272: 148.3 | AF272: 156.4 | AG272: =SUM(AE272:AF272) -> 304.7 | AH272: 183.5 | AI272: 147 | AJ272: =SUM(AH272:AI272) -> 330.5 | AK272: 151.8
A273: Rural | B273: 2020 | C273: August | D273: =IF(H273>120,IF(M273>120,"Yes","No"),"No") -> No | E273: 147.6 | F273: 187.2 | G273: 148.4 | H273: 153.3 | I273: 139.8 | J273: 146.9 | K273: 171 | L273: 149.9 | M273: 114.2 | N273: 160 | O273: 143.5 | P273: 161.5 | Q273: 155.3 | R273: =SUM(E273:Q273) -> 1978.6 | S273: 155.1 | T273: 149.3 | U273: 154.3 | V273: =SUM(S273:U273) -> 458.7 | W273: 139.25 | X273: 145.8 | Y273: 151.9 | Z273: =SUM(W273:Y273) -> 436.95 | AA273: 158.8 | AB273: 153.6 | AC273: =SUM(AA273:AB273) -> 312.4 | AD273: 143.6 | AE273: 152.2 | AF273: 162.7 | AG273: =SUM(AE273:AF273) -> 314.9 | AH273: 180.9 | AI273: 153 | AJ273: =SUM(AH273:AI273) -> 333.9 | AK273: 154.7
A274: Urban | B274: 2020 | C274: August | D274: =IF(H274>120,IF(M274>120,"Yes","No"),"No") -> No | E274: 151.6 | F274: 197.8 | G274: 154.5 | H274: 153.4 | I274: 133.4 | J274: 154.5 | K274: 191.9 | L274: 151.3 | M274: 116.8 | N274: 160 | O274: 136.5 | P274: 163.3 | Q274: 159.9 | R274: =SUM(E274:Q274) -> 2024.9 | S274: 150 | T274: 135.2 | U274: 147.8 | V274: =SUM(S274:U274) -> 433 | W274: 155.5 | X274: 138.3 | Y274: 144.5 | Z274: =SUM(W274:Y274) -> 438.3 | AA274: 148.7 | AB274: 155.2 | AC274: =SUM(AA274:AB274) -> 303.9 | AD274: 133.9 | AE274: 141.2 | AF274: 155.5 | AG274: =SUM(AE274:AF274) -> 296.7 | AH274: 187.2 | AI274: 144.8 | AJ274: =SUM(AH274:AI274) -> 332 | AK274: 152.9
A275: Rural+Urban | B275: 2020 | C275: August | D275: =IF(H275>120,IF(M275>120,"Yes","No"),"No") -> No | E275: 148.9 | F275: 190.9 | G275: 150.8 | H275: 153.3 | I275: 137.4 | J275: 150.4 | K275: 178.1 | L275: 150.4 | M275: 115.1 | N275: 160 | O275: 140.6 | P275: 162.3 | Q275: 157 | R275: =SUM(E275:Q275) -> 1995.2 | S275: 153.1 | T275: 143.4 | U275: 151.7 | V275: =SUM(S275:U275) -> 448.2 | W275: 155.5 | X275: 143 | Y275: 148.4 | Z275: =SUM(W275:Y275) -> 446.9 | AA275: 155 | AB275: 154.3 | AC275: =SUM(AA275:AB275) -> 309.3 | AD275: 138.5 | AE275: 146 | AF275: 158.5 | AG275: =SUM(AE275:AF275) -> 304.5 | AH275: 182.6 | AI275: 149 | AJ275: =SUM(AH275:AI275) -> 331.6 | AK275: 153.9
A276: Rural | B276: 2020 | C276: September | D276: =IF(H276>120,IF(M276>120,"Yes","No"),"No") -> No | E276: 146.9 | F276: 183.9 | G276: 149.5 | H276: 153.4 | I276: 140.4 | J276: 147 | K276: 178.8 | L276: 149.3 | M276: 115.1 | N276: 160 | O276: 145.4 | P276: 161.6 | Q276: 156.1 | R276: =SUM(E276:Q276) -> 1987.4 | S276: 155.4 | T276: 149.9 | U276: 154.6 | V276: =SUM(S276:U276) -> 459.9 | W276: 139.25 | X276: 146.4 | Y276: 151.6 | Z276: =SUM(W276:Y276) -> 437.25 | AA276: 159.1 | AB276: 157.4 | AC276: =SUM(AA276:AB276) -> 316.5 | AD276: 144.6 | AE276: 152.8 | AF276: 161.1 | AG276: =SUM(AE276:AF276) -> 313.9 | AH276: 182.9 | AI276: 153.7 | AJ276: =SUM(AH276:AI276) -> 336.6 | AK276: 155.4
A277: Urban | B277: 2020 | C277: September | D277: =IF(H277>120,IF(M277>120,"Yes","No"),"No") -> No | E277: 151.5 | F277: 193.1 | G277: 157.3 | H277: 153.9 | I277: 134.4 | J277: 155.4 | K277: 202 | L277: 150.8 | M277: 118.9 | N277: 160.9 | O277: 137.7 | P277: 164.4 | Q277: 161.3 | R277: =SUM(E277:Q277) -> 2041.6 | S277: 150.2 | T277: 136.3 | U277: 148.1 | V277: =SUM(S277:U277) -> 434.6 | W277: 156.3 | X277: 137.2 | Y277: 145.4 | Z277: =SUM(W277:Y277) -> 438.9 | AA277: 150 | AB277: 159.8 | AC277: =SUM(AA277:AB277) -> 309.8 | AD277: 135.1 | AE277: 141.8 | AF277: 154.9 | AG277: =SUM(AE277:AF277) -> 296.7 | AH277: 188.7 | AI277: 146 | AJ277: =SUM(AH277:AI277) -> 334.7 | AK277: 154
A278: Rural+Urban | B278: 2020 | C278: September | D278: =IF(H278>120,IF(M278>120,"Yes","No"),"No") -> No | E278: 148.4 | F278: 187.1 | G278: 152.5 | H278: 153.6 | I278: 138.2 | J278: 150.9 | K278: 186.7 | L278: 149.8 | M278: 116.4 | N278: 160.3 | O278: 142.2 | P278: 162.9 | Q278: 158 | R278: =SUM(E278:Q278) -> 2007 | S278: 153.4 | T278: 144.3 | U278: 152 | V278: =SUM(S278:U278) -> 449.7 | W278: 156.3 | X278: 142.9 | Y278: 148.7 | Z278: =SUM(W278:Y278) -> 447.9 | AA278: 155.6 | AB278: 158.4 | AC278: =SUM(AA278:AB278) -> 314 | AD278: 139.6 | AE278: 146.6 | AF278: 157.5 | AG278: =SUM(AE278:AF278) -> 304.1 | AH278: 184.4 | AI278: 150 | AJ278: =SUM(AH278:AI278) -> 334.4 | AK278: 154.7
... A374: Rural+Urban | B374: 2023 | C374: May | D374: =IF(H374>120,IF(M374>120,"Yes","No"),"No") -> Yes | E374: 173.7 | F374: 214.3 | G374: 173.2 | H374: 179.5 | I374: 170 | J374: 172.2 | K374: 161 | L374: 175.6 | M374: 122.7 | N374: 218 | O374: 173.4 | P374: 194.2 | Q374: 179.1 | R374: =SUM(E374:Q374) -> 2306.9 | S374: 187.3 | T374: 179.7 | U374: 186.2 | V374: =SUM(S374:U374) -> 553.2 | W374: 175.6 | X374: 182.8 | Y374: 175.2 | Z374: =SUM(W374:Y374) -> 533.6 | AA374: 185.7 | AB374: 185.2 | AC374: =SUM(AA374:AB374) -> 370.9 | AD374: 164.8 | AE374: 171.2 | AF374: 177.1 | AG374: =SUM(AE374:AF374) -> 348.3 | AH374: 201 | AI374: 175.7 | AJ374: =SUM(AH374:AI374) -> 376.7 | AK374: 179.1

Sheet Q1
A1: Total Average Contribution for each Categories (2013-2023) All Sectors Combined
A2: Category | B2: Index_Value | C2: Contribution_%
A3: Food Products | B3: =AVERAGE('Main Data'!R3:R374) -> 1824.5025 | C3: =(B3/$B$10)*100 -> 50.390698
A4: Clothing & Misc | B4: =AVERAGE('Main Data'!V3:V374) -> 420.3153 | C4: =(B4/$B$10)*100 -> 11.608634
A5: Housing & Misc | B5: =AVERAGE('Main Data'!Z3:Z374) -> 412.30683 | C5: =(B5/$B$10)*100 -> 11.387449
A6: Health and personal Care | B6: =AVERAGE('Main Data'!AC3:AC374) -> 271.77322 | C6: =(B6/$B$10)*100 -> 7.5060695
A7: Transport and communication | B7: =AVERAGE('Main Data'!AD3:AD374) -> 127.17049 | C7: =(B7/$B$10)*100 -> 3.5123054
A8: Education and Entertainment | B8: =AVERAGE('Main Data'!AG3:AG374) -> 275.02295 | C8: =(B8/$B$10)*100 -> 7.5958233
A9: Miscellaneuos | B9: =AVERAGE('Main Data'!AJ3:AJ374) -> 289.62158 | C9: =(B9/$B$10)*100 -> 7.9990211
A10: Total | B10: =SUM(B3:B9) -> 3620.7128 | C10: =SUM(C3:C9) -> 100
A29: Latest Months Data Contribution ( May, 2023) All Sectors Combined
A30: Category | B30: CPI Index_Value | C30: Contribution_%
A31: Food Products | B31: =AVERAGEIFS('Main Data'!R3:R374,'Main Data'!$B$3:$B$374,"2023",'Main Data'!$C$3:$C$374,"May") -> 2310.9 | C31: =(B31/$B$38)*100 -> 49.756161
A32: Clothing & Misc | B32: =AVERAGEIFS('Main Data'!$V$3:$V$374,'Main Data'!$B$3:$B$374,"2023",'Main Data'!$C$3:$C$374,"May") -> 550.6 | C32: =(B32/$B$38)*100 -> 11.85501
A33: Housing & Misc | B33: =AVERAGEIFS('Main Data'!$Z$3:$Z$374,'Main Data'!$B$3:$B$374,"2023",'Main Data'!$C$3:$C$374,"May") -> 521.41667 | C33: =(B33/$B$38)*100 -> 11.226661
A34: Health and personal Care | B34: =AVERAGEIFS('Main Data'!$AC$3:$AC$374,'Main Data'!$B$3:$B$374,"2023",'Main Data'!$C$3:$C$374,"May") -> 370.46667 | C34: =(B34/$B$38)*100 -> 7.9765455
A35: Transport and communication | B35: =AVERAGEIFS('Main Data'!$AD$3:$AD$374,'Main Data'!$B$3:$B$374,"2023",'Main Data'!$C$3:$C$374,"May") -> 164.96667 | C35: =(B35/$B$38)*100 -> 3.5519096
A36: Education and Entertainment | B36: =AVERAGEIFS('Main Data'!$AG$3:$AG$374,'Main Data'!$B$3:$B$374,"2023",'Main Data'!$C$3:$C$374,"May") -> 348.8 | C36: =(B36/$B$38)*100 -> 7.5100389
A37: Miscellaneuos | B37: =AVERAGEIFS('Main Data'!$AJ$3:$AJ$374,'Main Data'!$B$3:$B$374,"2023",'Main Data'!$C$3:$C$374,"May") -> 377.3 | C37: =(B37/$B$38)*100 -> 8.1236745
A38: Total | B38: =SUM(B31:B37) -> 4644.45 | C38: =SUM(C31:C37) -> 100
A55: Latest Months Data Contribution ( May, 2023) Rural Sector
A56: Category | B56: Index_Value | C56: Contribution_%
A57: Food Products | B57: 2290.7 | C57: =(B57/$B$64) -> 0.49389291
A58: Clothing & Misc | B58: 569.9 | C58: =(B58/$B$64) -> 0.12287492
A59: Housing & Misc | B59: 501.55 | C59: =(B59/$B$64) -> 0.10813812
A60: Health and personal Care | B60: 372.7 | C60: =(B60/$B$64) -> 0.080357047
A61: Transport and communication | B61: 169.7 | C61: =(B61/$B$64) -> 0.036588653
A62: Education and Entertainment | B62: 354.1 | C62: =(B62/$B$64) -> 0.076346741
A63: Miscellaneuos | B63: 379.4 | C63: =(B63/$B$64) -> 0.081801619
A64: Total | B64: =SUM(B57:B63) -> 4638.05 | C64: =SUM(C57:C63) -> 1
A66: Latest Months Data Contribution ( May, 2023) Rural+Urban Sector
A67: Category | B67: Index_Value | C67: Contribution_%
A68: Food Products | B68: 2306.9 | C68: =(B68/$B$75) -> 0.49563854
A69: Clothing & Misc | B69: 553.2 | C69: =(B69/$B$75) -> 0.11885528
A70: Housing & Misc | B70: 533.6 | C70: =(B70/$B$75) -> 0.11464421
A71: Health and personal Care | B71: 370.9 | C71: =(B71/$B$75) -> 0.079688037
A72: Transport and communication | B72: 164.8 | C72: =(B72/$B$75) -> 0.035407356
A73: Education and Entertainment | B73: 348.3 | C73: =(B73/$B$75) -> 0.074832417
A74: Miscellaneuos | B74: 376.7 | C74: =(B74/$B$75) -> 0.08093417
A75: Total | B75: =SUM(B68:B74) -> 4654.4 | C75: =SUM(C68:C74) -> 1
...

Sheet Pivot Q1
A1: Year | B1: (All)
A2: Sector | B2: (All)
A4: Row Labels | B4: Average of Total (Food Products) | C4: Average of Total (Clothing & MISC) | D4: Average of Total (Housing & MISC) | E4: Average of Total (Health & Personal Care) | F4: Average of Transport and communication | G4: Average of Total Edu & Ent | H4: Average of Total (MISC)
A5: January | B5: 1805.7939 | C5: 417.5303 | D5: 409.99242 | E5: 270.55758 | F5: 126.2 | G5: 273.07273 | H5: 287.31212
A6: February | B6: 1795.6455 | C6: 419.53333 | D6: 412.20455 | E6: 272.24545 | F6: 126.77576 | G6: 273.97576 | H6: 288.69091
A7: March | B7: 1805.8344 | C7: 423.32188 | D7: 415.89531 | E7: 274.62812 | F7: 127.75937 | G7: 276.43125 | H7: 291.6875
A8: April | B8: 1802.5926 | C8: 419.69259 | D8: 410.60185 | E8: 271.13704 | F8: 127.9 | G8: 271.72222 | H8: 286.92593
A9: May | B9: 1818.0867 | C9: 423.60667 | D9: 414.29667 | E9: 273.29333 | F9: 128.23 | G9: 274.99667 | H9: 290.10667
A10: June | B10: 1806.34 | C10: 414.81667 | D10: 406.97333 | E10: 267.49667 | F10: 125.66667 | G10: 271.99667 | H10: 286.43333
A11: July | B11: 1826.11 | C11: 416.53667 | D11: 408.82333 | E11: 268.51 | F11: 126.28 | G11: 273.96667 | H11: 287.71333
A12: August | B12: 1835.5633 | C12: 418.54333 | D12: 410.77 | E12: 270.38 | F12: 126.83 | G12: 275.30333 | H12: 289.17333
A13: September | B13: 1835.09 | C13: 420.34 | D13: 412.24 | E13: 271.9 | F13: 127.48 | G13: 276.14333 | H13: 290.64667
A14: October | B14: 1851.6833 | C14: 422.13333 | D14: 414.46667 | E14: 273.17333 | F14: 127.86667 | G14: 277.08 | H14: 291.84333
A15: November | B15: 1878.5276 | C15: 427.12759 | D15: 418.33276 | E15: 276.18621 | F15: 128.35172 | G15: 280.21379 | H15: 295.36897
A16: December | B16: 1859.17 | C16: 425.97667 | D16: 417.20333 | E16: 275.25333 | F16: 128.02667 | G16: 279.01333 | H16: 294.00333
... A19: Grand Total | B19: 1824.5025 | C19: 420.3153 | D19: 412.30683 | E19: 271.77322 | F19: 127.17049 | G19: 275.02295 | H19: 289.62158
A22: Year | B22: 2023
A23: Sector | B23: Urban
A25: Row Labels | B25: Average of Total (Food Products) | C25: Average of Total (Clothing & MISC) | D25: Average of Total (Housing & MISC) | E25: Average of Total (Health & Personal Care) | F25: Average of Transport and communication | G25: Average of Total Edu & Ent | H25: Average of Total (MISC)
A26: May | B26: 2335.1 | C26: 528.7 | D26: 529.1 | E26: 367.8 | F26: 160.4 | G26: 344 | H26: 375.8
A27: Grand Total | B27: 2335.1 | C27: 528.7 | D27: 529.1 | E27: 367.8 | F27: 160.4 | G27: 344 | H27: 375.8

Sheet Q2
A1: Sector
A2: Rural + Urban
A4: Year | B4: General Index | C4: YoY Inflation (%)
A5: 2017 | B5: =AVERAGEIF('Q2 Data'!$B$2:$B$77,'Q2'!A5,'Q2 Data'!$D$2:$D$77) -> 133.5
A6: 2018 | B6: =AVERAGEIF('Q2 Data'!$B$2:$B$77,'Q2'!A6,'Q2 Data'!$D$2:$D$77) -> 138.775 | C6: =((B6-B5)/B5)*100 -> 3.9513109
A7: 2019 | B7: =AVERAGEIF('Q2 Data'!$B$2:$B$77,'Q2'!A7,'Q2 Data'!$D$2:$D$77) -> 144.18182 | C7: =((B7-B6)/B6)*100 -> 3.8961039
A8: 2020 | B8: =AVERAGEIF('Q2 Data'!$B$2:$B$77,'Q2'!A8,'Q2 Data'!$D$2:$D$77) -> 153.38 | C8: =((B8-B7)/B7)*100 -> 6.3795712
A9: 2021 | B9: =AVERAGEIF('Q2 Data'!$B$2:$B$77,'Q2'!A9,'Q2 Data'!$D$2:$D$77) -> 161.45833 | C9: =((B9-B8)/B8)*100 -> 5.2668753
A10: 2022 | B10: =AVERAGEIF('Q2 Data'!$B$2:$B$77,'Q2'!A10,'Q2 Data'!$D$2:$D$77) -> 172.15 | C10: =((B10-B9)/B9)*100 -> 6.6219355
A11: 2023 | B11: =AVERAGEIF('Q2 Data'!$B$2:$B$77,'Q2'!A11,'Q2 Data'!$D$2:$D$77) -> 177.62 | C11: =((B11-B10)/B10)*100 -> 3.1774615
A15: Rural
A16: Year | B16: General Index | C16: YoY Inflation (%)
A17: 2017 | B17: =AVERAGEIF('Q2 Data'!$G$2:$G$77,'Q2'!A17,'Q2 Data'!$I$2:$I$77) -> 135.63333
A18: 2018 | B18: =AVERAGEIF('Q2 Data'!$G$2:$G$77,'Q2'!A18,'Q2 Data'!$I$2:$I$77) -> 140.73333 | C18: =((B18-B17)/B17)*100 -> 3.7601376
A19: 2019 | B19: =AVERAGEIF('Q2 Data'!$G$2:$G$77,'Q2'!A19,'Q2 Data'!$I$2:$I$77) -> 145.18182 | C19: =((B19-B18)/B18)*100 -> 3.1609319
A20: 2020 | B20: =AVERAGEIF('Q2 Data'!$G$2:$G$77,'Q2'!A20,'Q2 Data'!$I$2:$I$77) -> 154.56 | C20: =((B20-B19)/B19)*100 -> 6.4596118
A21: 2021 | B21: =AVERAGEIF('Q2 Data'!$G$2:$G$77,'Q2'!A21,'Q2 Data'!$I$2:$I$77) -> 162.03333 | C21: =((B21-B20)/B20)*100 -> 4.8352312
A22: 2022 | B22: =AVERAGEIF('Q2 Data'!$G$2:$G$77,'Q2'!A22,'Q2 Data'!$I$2:$I$77) -> 173.125 | C22: =((B22-B21)/B21)*100 -> 6.8452993
A23: 2023 | B23: =AVERAGEIF('Q2 Data'!$G$2:$G$77,'Q2'!A23,'Q2 Data'!$I$2:$I$77) -> 178.48 | C23: =((B23-B22)/B22)*100 -> 3.0931408
A30: Urban
A31: Year | B31: General Index | C31: YoY Inflation (%)
A32: 2017 | B32: =AVERAGEIF('Q2 Data'!$L$2:$L$77,'Q2'!A32,'Q2 Data'!$N$2:$N$77) -> 131.025
A33: 2018 | B33: =AVERAGEIF('Q2 Data'!$L$2:$L$77,'Q2'!A33,'Q2 Data'!$N$2:$N$77) -> 136.5 | C33: =((B33-B32)/B32)*100 -> 4.1785919
A34: 2019 | B34: =AVERAGEIF('Q2 Data'!$L$2:$L$77,'Q2'!A34,'Q2 Data'!$N$2:$N$77) -> 143.01818 | C34: =((B34-B33)/B33)*100 -> 4.7752248
A35: 2020 | B35: =AVERAGEIF('Q2 Data'!$L$2:$L$77,'Q2'!A35,'Q2 Data'!$N$2:$N$77) -> 152.05 | C35: =((B35-B34)/B34)*100 -> 6.3151538
A36: 2021 | B36: =AVERAGEIF('Q2 Data'!$L$2:$L$77,'Q2'!A36,'Q2 Data'!$N$2:$N$77) -> 160.75833 | C36: =((B36-B35)/B35)*100 -> 5.7272827
A37: 2022 | B37: =AVERAGEIF('Q2 Data'!$L$2:$L$77,'Q2'!A37,'Q2 Data'!$N$2:$N$77) -> 170.95 | C37: =((B37-B36)/B36)*100 -> 6.3397439
A38: 2023 | B38: =AVERAGEIF('Q2 Data'!$L$2:$L$77,'Q2'!A38,'Q2 Data'!$N$2:$N$77) -> 176.62 | C38: =((B38-B37)/B37)*100 -> 3.3167593
C40: =AVERAGE(C33:C38) -> 5.1087927

Sheet Q2 Data
A1: Sector | B1: Year | C1: Month | D1: General index | F1: Sector | G1: Year | H1: Month | I1: General index | K1: Sector | L1: Year | M1: Month | N1: General index
A2: Rural+Urban | B2: 2017 | C2: January | D2: 130.3 | F2: Rural | G2: 2017 | H2: January | I2: 132.4 | K2: Urban | L2: 2017 | M2: January | N2: 127.8
A3: Rural+Urban | B3: 2017 | C3: February | D3: 130.6 | F3: Rural | G3: 2017 | H3: February | I3: 132.6 | K3: Urban | L3: 2017 | M3: February | N3: 128.2
A4: Rural+Urban | B4: 2017 | C4: March | D4: 130.9 | F4: Rural | G4: 2017 | H4: March | I4: 132.8 | K4: Urban | L4: 2017 | M4: March | N4: 128.7
A5: Rural+Urban | B5: 2017 | C5: April | D5: 131.1 | F5: Rural | G5: 2017 | H5: April | I5: 132.9 | K5: Urban | L5: 2017 | M5: April | N5: 129.1
A6: Rural+Urban | B6: 2017 | C6: May | D6: 131.4 | F6: Rural | G6: 2017 | H6: May | I6: 133.3 | K6: Urban | L6: 2017 | M6: May | N6: 129.3
A7: Rural+Urban | B7: 2017 | C7: June | D7: 132 | F7: Rural | G7: 2017 | H7: June | I7: 133.9 | K7: Urban | L7: 2017 | M7: June | N7: 129.9
A8: Rural+Urban | B8: 2017 | C8: July | D8: 134.2 | F8: Rural | G8: 2017 | H8: July | I8: 136.2 | K8: Urban | L8: 2017 | M8: July | N8: 131.8
A9: Rural+Urban | B9: 2017 | C9: August | D9: 135.4 | F9: Rural | G9: 2017 | H9: August | I9: 137.8 | K9: Urban | L9: 2017 | M9: August | N9: 132.7
A10: Rural+Urban | B10: 2017 | C10: September | D10: 135.2 | F10: Rural | G10: 2017 | H10: September | I10: 137.6 | K10: Urban | L10: 2017 | M10: September | N10: 132.4
A11: Rural+Urban | B11: 2017 | C11: October | D11: 136.1 | F11: Rural | G11: 2017 | H11: October | I11: 138.3 | K11: Urban | L11: 2017 | M11: October | N11: 133.5
A12: Rural+Urban | B12: 2017 | C12: November | D12: 137.6 | F12: Rural | G12: 2017 | H12: November | I12: 140 | K12: Urban | L12: 2017 | M12: November | N12: 134.8
A13: Rural+Urban | B13: 2017 | C13: December | D13: 137.2 | F13: Rural | G13: 2017 | H13: December | I13: 139.8 | K13: Urban | L13: 2017 | M13: December | N13: 134.1
... A39: Rural+Urban | B39: 2020 | C39: March | D39: 148.6 | F39: Rural | G39: 2020 | H39: March | I39: 149.8 | K39: Urban | L39: 2020 | M39: March | N39: 147.3
A40: Rural+Urban | B40: 2020 | C40: April | D40: NA | F40: Rural | G40: 2020 | H40: April | I40: NA | K40: Urban | L40: 2020 | M40: April | N40: NA
A41: Rural+Urban | B41: 2020 | C41: May | D41: NA | F41: Rural | G41: 2020 | H41: May | I41: NA | K41: Urban | L41: 2020 | M41: May | N41: NA
A42: Rural+Urban | B42: 2020 | C42: June | D42: 151.8 | F42: Rural | G42: 2020 | H42: June | I42: 152.7 | K42: Urban | L42: 2020 | M42: June | N42: 150.8
A43: Rural+Urban | B43: 2020 | C43: July | D43: 151.8 | F43: Rural | G43: 2020 | H43: July | I43: 152.7 | K43: Urban | L43: 2020 | M43: July | N43: 150.8
A44: Rural+Urban | B44: 2020 | C44: August | D44: 153.9 | F44: Rural | G44: 2020 | H44: August | I44: 154.7 | K44: Urban | L44: 2020 | M44: August | N44: 152.9
A45: Rural+Urban | B45: 2020 | C45: September | D45: 154.7 | F45: Rural | G45: 2020 | H45: September | I45: 155.4 | K45: Urban | L45: 2020 | M45: September | N45: 154
A46: Rural+Urban | B46: 2020 | C46: October | D46: 156.4 | F46: Rural | G46: 2020 | H46: October | I46: 157.5 | K46: Urban | L46: 2020 | M46: October | N46: 155.2
A47: Rural+Urban | B47: 2020 | C47: November | D47: 158.4 | F47: Rural | G47: 2020 | H47: November | I47: 159.8 | K47: Urban | L47: 2020 | M47: November | N47: 156.7
A48: Rural+Urban | B48: 2020 | C48: December | D48: 158.9 | F48: Rural | G48: 2020 | H48: December | I48: 160.7 | K48: Urban | L48: 2020 | M48: December | N48: 156.9
A49: Rural+Urban | B49: 2021 | C49: January | D49: 157.3 | F49: Rural | G49: 2021 | H49: January | I49: 158.5 | K49: Urban | L49: 2021 | M49: January | N49: 156
A50: Rural+Urban | B50: 2021 | C50: February | D50: 156.6 | F50: Rural | G50: 2021 | H50: February | I50: 156.7 | K50: Urban | L50: 2021 | M50: February | N50: 156.5
A51: Rural+Urban | B51: 2021 | C51: March | D51: 156.8 | F51: Rural | G51: 2021 | H51: March | I51: 156.7 | K51: Urban | L51: 2021 | M51: March | N51: 156.9
A52: Rural+Urban | B52: 2021 | C52: April | D52: 157.8 | F52: Rural | G52: 2021 | H52: April | I52: 157.6 | K52: Urban | L52: 2021 | M52: April | N52: 158
A53: Rural+Urban | B53: 2021 | C53: May | D53: 160.4 | F53: Rural | G53: 2021 | H53: May | I53: 161.1 | K53: Urban | L53: 2021 | M53: May | N53: 159.5
... A77: Rural+Urban | B77: 2023 | C77: May | D77: 179.1 | F77: Rural | G77: 2023 | H77: May | I77: 179.8 | K77: Urban | L77: 2023 | M77: May | N77: 178.2

Sheet Q4 Summary
A1: Period definitions used
A3: Pre: 2019-03-01 → 2020-02-01
A5: Post: 2020-04-01 → 2021-03-01
A7: Summary table (averages)
A8: Rural + Urban
A9: Category | B9: Pre YoY mean (%) | C9: Post YoY mean (%) | D9: Δ YoY (Post−Pre) (pp) | E9: Pre MoM mean (%) | F9: Post MoM mean (%) | G9: Δ MoM (pp)
A10: Food Index (unweighted avg of food items) | B10: 5.6993896 | C10: 8.7057269 | D10: =C10-B10 -> 3.0063372 | E10: 0.88446947 | F10: 0.53934237 | G10: =F10-E10 -> -0.34512711
A11: Health | B11: 7.2056466 | C11: 4.8751774 | D11: =C11-B11 -> -2.3304692 | E11: 0.37383013 | F11: 0.35857623 | G11: =F11-E11 -> -0.015253896
A12: Transport and communication | B12: 2.5188855 | C12: 9.9562101 | D12: =C12-B12 -> 7.4373246 | E12: 0.46170003 | F12: 0.8934069 | G12: =F12-E12 -> 0.43170687
A13: Household goods & services | B13: 4.3492265 | C13: 2.3991885 | D13: =C13-B13 -> -1.950038 | E13: 0.27640526 | F13: 0.35915648 | G13: =F13-E13 -> 0.082751226
A29: Rural
A30: Category | B30: Pre YoY mean (%) | C30: Post YoY mean (%) | D30: Δ YoY (Post−Pre) (pp) | E30: Pre MoM mean (%) | F30: Post MoM mean (%) | G30: Δ MoM (pp)
A31: Food Index (unweighted avg of food items) | B31: 4.1578612 | C31: 8.3497725 | D31: =C31-B31 -> 4.1919113 | E31: 0.86864411 | F31: 0.52230638 | G31: =F31-E31 -> -0.34633774
A32: Health | B32: 8.2508309 | C32: 4.1131615 | D32: =C32-B32 -> -4.1376694 | E32: 0.37503376 | F32: 0.24476176 | G32: =F32-E32 -> -0.130272
A33: Transport and communication | B33: 3.3878176 | C33: 9.5815983 | D33: =C33-B33 -> 6.1937807 | E33: 0.46939209 | F33: 0.75685713 | G33: =F33-E33 -> 0.28746505
A34: Household goods & services | B34: 2.0931676 | C34: -0.0081727509 | D34: =C34-B34 -> -2.1013403 | E34: 0.05330966 | F34: 0.10986242 | G34: =F34-E34 -> 0.056552757
A50: Urban
A51: Category | B51: Pre YoY mean (%) | C51: Post YoY mean (%) | D51: Δ YoY (Post−Pre) (pp) | E51: Pre MoM mean (%) | F51: Post MoM mean (%) | G51: Δ MoM (pp)
A52: Food Index (unweighted avg of food items) | B52: 8.4972233 | C52: 9.3240918 | D52: =C52-B52 -> 0.82686846 | E52: 0.91718734 | F52: 0.57144883 | G52: =F52-E52 -> -0.34573851
A53: Health | B53: 5.5181575 | C53: 6.2209103 | D53: =C53-B53 -> 0.70275277 | E53: 0.3799945 | F53: 0.56588159 | G53: =F53-E53 -> 0.18588708
A54: Transport and communication | B54: 1.516751 | C54: 10.290633 | D54: =C54-B54 -> 8.7738819 | E54: 0.45127334 | F54: 1.0296677 | G54: =F54-E54 -> 0.57839437
A55: Household goods & services | B55: 4.1949812 | C55: 3.3571279 | D55: =C55-B55 -> -0.8378533 | E55: 0.31721374 | F55: 0.40374129 | G55: =F55-E55 -> 0.08652755

Sheet Q3
A1: Rural+Urban
A2: Sector | B2: Year | C2: Date | D2: Month | E2: Cereals and products | F2: Meat and fish | G2: Egg | H2: Milk and products | I2: Oils and fats | J2: Fruits | K2: Vegetables | L2: Pulses and products | M2: Sugar and Confectionery | N2: Spices | O2: Non-alcoholic beverages | P2: Prepared meals, snacks, sweets etc. | Q2: Food and beverages | R2: Food Index | S2: MoM Inflation (%)
A3: Rural+Urban | B3: 2022 | C3: =DATE(B3,MONTH(1&D3),1) -> 44713 | D3: June | E3: 155 | F3: 219.4 | G3: 170.8 | H3: 165.8 | I3: 200.9 | J3: 169.7 | K3: 182.3 | L3: 164.3 | M3: 119.9 | N3: 187.1 | O3: 167.9 | P3: 183.9 | Q3: 174.9 | R3: 173.99231
A4: Rural+Urban | B4: 2022 | C4: =DATE(B4,MONTH(1&D4),1) -> 44743 | D4: July | E4: 156.5 | F4: 213 | G4: 175.2 | H4: 166.6 | I4: 195.8 | J4: 174.2 | K4: 182.1 | L4: 164.3 | M4: 120 | N4: 190 | O4: 168.4 | P4: 185.2 | Q4: 175 | R4: 174.33077 | S4: =IF(R3=0,"",((R4-R3)/R3)*100) -> 0.19452673
A5: Rural+Urban | B5: 2022 | C5: =DATE(B5,MONTH(1&D5),1) -> 44774 | D5: August | E5: 160.3 | F5: 206.5 | G5: 169.2 | H5: 168.1 | I5: 192.4 | J5: 172.9 | K5: 186.7 | L5: 167.2 | M5: 120.9 | N5: 193.6 | O5: 168.8 | P5: 186.3 | Q5: 176.3 | R5: 174.55385 | S5: =IF(R4=0,"",((R5-R4)/R4)*100) -> 0.12796188
A6: Rural+Urban | B6: 2022 | C6: =DATE(B6,MONTH(1&D6),1) -> 44805 | D6: September | E6: 163.5 | F6: 209.2 | G6: 169.7 | H6: 169.7 | I6: 188.7 | J6: 165.7 | K6: 191.8 | L6: 169.1 | M6: 121.6 | N6: 197.3 | O6: 169.4 | P6: 187.4 | Q6: 177.8 | R6: 175.45385 | S6: =IF(R5=0,"",((R6-R5)/R5)*100) -> 0.51560021
A7: Rural+Urban | B7: 2022 | C7: =DATE(B7,MONTH(1&D7),1) -> 44835 | D7: October | E7: 165.2 | F7: 210.9 | G7: 170.9 | H7: 170.9 | I7: 186.5 | J7: 163.8 | K7: 199.7 | L7: 169.8 | M7: 121.9 | N7: 199.9 | O7: 169.9 | P7: 188.3 | Q7: 179.6 | R7: 176.71538 | S7: =IF(R6=0,"",((R7-R6)/R6)*100) -> 0.71901442
A8: Rural+Urban | B8: 2022 | C8: =DATE(B8,MONTH(1&D8),1) -> 44866 | D8: November | E8: 167.4 | F8: 209.4 | G8: 181.4 | H8: 172.3 | I8: 188.9 | J8: 160.7 | K8: 183.1 | L8: 170.5 | M8: 122.1 | N8: 202.8 | O8: 170.4 | P8: 189.5 | Q8: 178.3 | R8: 176.67692 | S8: =IF(R7=0,"",((R8-R7)/R7)*100) -> -0.02176468
A9: Rural+Urban | B9: 2022 | C9: =DATE(B9,MONTH(1&D9),1) -> 44896 | D9: December | E9: 169.2 | F9: 209 | G9: 190.2 | H9: 173.6 | I9: 188.5 | J9: 158 | K9: 159.9 | L9: 170.8 | M9: 121.8 | N9: 205.2 | O9: 171 | P9: 190.3 | Q9: 175.9 | R9: 175.64615 | S9: =IF(R8=0,"",((R9-R8)/R8)*100) -> -0.58342041
A10: Rural+Urban | B10: 2023 | C10: =DATE(B10,MONTH(1&D10),1) -> 44927 | D10: January | E10: 173.8 | F10: 210.7 | G10: 194.5 | H10: 174.6 | I10: 187.2 | J10: 158.3 | K10: 153.9 | L10: 170.9 | M10: 121.1 | N10: 208.4 | O10: 171.4 | P10: 191.2 | Q10: 176.7 | R10: 176.36154 | S10: =IF(R9=0,"",((R10-R9)/R9)*100) -> 0.40728738
A11: Rural+Urban | B11: 2023 | C11: =DATE(B11,MONTH(1&D11),1) -> 44958 | D11: February | E11: 174.4 | F11: 207.7 | G11: 175.2 | H11: 177.3 | I11: 179.3 | J11: 169.5 | K11: 152.7 | L11: 171 | M11: 120 | N11: 209.7 | O11: 172.3 | P11: 193 | Q11: 177 | R11: 175.31538 | S11: =IF(R10=0,"",((R11-R10)/R10)*100) -> -0.59318707
A12: Rural+Urban | B12: 2023 | C12: =DATE(B12,MONTH(1&D12),1) -> 44986 | D12: March | E12: 174.4 | F12: 207.7 | G12: 175.2 | H12: 177.3 | I12: 179.2 | J12: 169.5 | K12: 152.8 | L12: 171.1 | M12: 120 | N12: 209.7 | O12: 172.3 | P12: 193 | Q12: 177 | R12: 175.32308 | S12: =IF(R11=0,"",((R12-R11)/R11)*100) -> 0.0043876969
A13: Rural+Urban | B13: 2023 | C13: =DATE(B13,MONTH(1&D13),1) -> 45017 | D13: April | E13: 173.8 | F13: 209.3 | G13: 169.6 | H13: 178.4 | I13: 174.9 | J13: 176.3 | K13: 155.4 | L13: 173.4 | M13: 121.3 | N13: 212.9 | O13: 172.9 | P13: 193.5 | Q13: 177.9 | R13: 176.12308 | S13: =IF(R12=0,"",((R13-R12)/R12)*100) -> 0.45630046
A14: Rural+Urban | B14: 2023 | C14: =DATE(B14,MONTH(1&D14),1) -> 45047 | D14: May | E14: 173.7 | F14: 214.3 | G14: 173.2 | H14: 179.5 | I14: 170 | J14: 172.2 | K14: 161 | L14: 175.6 | M14: 122.7 | N14: 218 | O14: 173.4 | P14: 194.2 | Q14: 179.1 | R14: 177.45385 | S14: =IF(R13=0,"",((R14-R13)/R13)*100) -> 0.7555905
A16: Food subcategory changes | B16: Start (Jun 2022) | C16: End (May 2023) | D16: Absolute Change | E16: Percentage Change (%) | R16: Max MoM | S16: =MAX(S4:S14) -> 0.7555905
A17: Spices | B17: 187.1 | C17: 218 | D17: =C17-B17 -> 30.9 | E17: =D17/B17 -> 0.16515232 | R17: Month for Max | S17: =INDEX(C3:C14,MATCH(S16,S3:S14,0)) -> 45047
A18: Cereals and products | B18: 155 | C18: 173.7 | D18: =C18-B18 -> 18.7 | E18: =D18/B18 -> 0.12064516
A19: Milk and products | B19: 165.8 | C19: 179.5 | D19: =C19-B19 -> 13.7 | E19: =D19/B19 -> 0.082629674 | S19: Min MoM | T19: =MIN(S4:S14) -> -0.59318707
A20: Pulses and products | B20: 164.3 | C20: 175.6 | D20: =C20-B20 -> 11.3 | E20: =D20/B20 -> 0.068776628 | S20: Month for Min | T20: =INDEX(C3:C14,MATCH(T19,S3:S14,0)) -> 44958
A21: Prepared meals, snacks, sweets etc. | B21: 183.9 | C21: 194.2 | D21: =C21-B21 -> 10.3 | E21: =D21/B21 -> 0.0560087
